Workbook

Sheet Deckblatt
B3: Campus Elgg – Investoren-Memo & Renditemodell
B6: Total Cost of Ownership · Flächenspiegel · Mietzinsmodell · Renditeanalyse
B8: Projekt | C8: Campus Elgg – Mischnutzung Gewerbe / Büro / Wotel
B9: Standort | C9: Elgg, Region Winterthur, Schweiz
B10: Erstellt für | C10: Zin Tetris AG / VR Viaholding AG
B11: Stand | C11: Mai 2026
B12: Quelle | C12: DEV_02_Campursus_TCO_Zin_InvestorenMemo.xlsx (Reiter «08 Quelldaten»)
B14: Inhalt der Arbeitsmappe
B15: 01 Cockpit | C15: Executive Overview – KPIs, Investitionsvolumen, Mietertrag, Bruttorendite
B16: 02 Renditeanalyse | C16: Sensitivität, Brutto-, Netto-, EK-Rendite
B17: 03 Flächenspiegel | C17: Mietpreise pro m², änderbar pro Haus A/B/C, Aufteilung pro Geschoss
B18: 04 Gebäudekennzahlen | C18: Geschossflächen (GF), Volumen (GV), Kennwerte je Haus
B19: 05 Kostenschätzung | C19: Anlagekosten BKP 0–9, Total Investitionskosten und CHF/m² GF
B20: 06 Etappe 2 | C20: 2. Etappe (3 weitere Häuser) – Ausweis Etappe 1 / 2 / Total
B21: 07 Grundstück | C21: Platzhalter Grundstücksflächen, Landwerte, Ausnützung
B22: 08 Quelldaten | C22: Originaldaten aus Tetris-Datei – unverändert, zur Nachvollziehbarkeit
B23: 09 Prozess & Next Steps | C23: Vorgehen, offene Punkte, nächste Arbeitsschritte
B25: Farbcode (Industrie-Standard Financial Modelling)
B26: Blaue Schrift | C26: Eingaben / Annahmen – können verändert werden
B27: Schwarze Schrift | C27: Formeln / berechnete Werte
B28: Grüne Schrift | C28: Verlinkung aus anderem Tabellenblatt
B29: Gelber Hintergrund | C29: Schlüsselannahmen – regelmässig prüfen

Sheet 01 Cockpit
B2: Campus Elgg – Investoren-Cockpit
B3: Executive Overview: Investition · Mieten · Rendite – Etappe 1 vs. Gesamtprojekt
B5: ETAPPE 1 (3 Häuser)
B6: Anlagekosten Total | D6: Vermietbare Fläche | F6: Soll-Mietertrag p.a.
B7: =Invest_E1 -> 37500000 | D7: =HNF_E1_Total -> 7051.82 | F7: =Mietertrag_E1_Soll -> 2054973.6
B8: BKP 0–9, 3 Häuser | D8: Hauptnutzfläche (HNF) | F8: Volle Vermietung
B10: Effektiv-Mietertrag p.a. | D10: Bruttorendite (eff.) | F10: Nettorendite
B11: =Mietertrag_E1_eff -> 1952224.9 | D11: =BruttoRendite_E1_eff -> 0.052059331 | F11: =NettoRendite_E1 -> 0.039455493
B12: Nach Mietausfall | D12: Effektivmiete / Invest | F12: NOI / Invest
B14: GESAMTPROJEKT (Etappe 1 + 2 = 6 Häuser)
B15: Anlagekosten Total | D15: Vermietbare Fläche | F15: Soll-Mietertrag p.a.
B16: =Invest_Total -> 75000000 | D16: =HNF_Total -> 14103.64 | F16: =Mietertrag_Total_Soll -> 4151046.7
B17: Gesamtes Projekt | D17: Hauptnutzfläche (HNF) | F17: Volle Vermietung
B19: Effektiv-Mietertrag p.a. | D19: Bruttorendite (eff.) | F19: EK-Rendite
B20: =Mietertrag_Total_eff -> 3838690.7 | D20: =BruttoRendite_Total_eff -> 0.051182542 | F20: =EKRendite_Total -> 0.06984222
B21: Nach Mietausfall | D21: Effektivmiete / Invest | F21: Cash-on-Cash
B23: Übersichtstabelle Etappen
B24: Kennzahl | E24: Etappe 1 | F24: Etappe 2 | G24: Total Projekt
B25: Anlagekosten | E25: =Invest_E1 -> 37500000 | F25: =Invest_E2 -> 37500000 | G25: =Invest_Total -> 75000000
B26: Soll-Mietertrag p.a. | E26: =Mietertrag_E1_Soll -> 2054973.6 | F26: =Mietertrag_Total_Soll-Mietertrag_E1_Soll -> 2096073.1 | G26: =Mietertrag_Total_Soll -> 4151046.7
B27: Effektiv-Mietertrag | E27: =Mietertrag_E1_eff -> 1952224.9 | F27: =Mietertrag_Total_eff-Mietertrag_E1_eff -> 1886465.8 | G27: =Mietertrag_Total_eff -> 3838690.7
B28: HNF (m²) | E28: =HNF_E1_Total -> 7051.82 | F28: =HNF_Total-HNF_E1_Total -> 7051.82 | G28: =HNF_Total -> 14103.64
B29: Bruttorendite (eff.) | E29: =BruttoRendite_E1_eff -> 0.052059331 | G29: =BruttoRendite_Total_eff -> 0.051182542
B30: Nettorendite | E30: =NettoRendite_E1 -> 0.039455493 | G30: =NettoRendite_Total -> 0.038452666
B31: EK-Rendite | E31: =EKRendite_E1 -> 0.073184977 | G31: =EKRendite_Total -> 0.06984222
B34: Mietertrag pro Geschoss & Haus (Etappe 1)
B35: Nutzungstyp | C35: Haus A | D35: Haus B | E35: Haus C | F35: Total E1
B36: EG (Gewerbe) | C36: =SUM('03 Flächenspiegel'!H28:H31) -> 178179.96 | D36: =SUM('03 Flächenspiegel'!H50:H53) -> 178179.96 | E36: =SUM('03 Flächenspiegel'!H72:H75) -> 173967.36 | F36: =SUM(C36:E36) -> 530327.28
B37: OG (Büro/Gewerbe) | C37: =SUM('03 Flächenspiegel'!H32:H37) -> 124216.8 | D37: =SUM('03 Flächenspiegel'!H54:H59) -> 124216.8 | E37: =SUM('03 Flächenspiegel'!H76:H81) -> 139717.2 | F37: =SUM(C37:E37) -> 388150.8
B38: AT (Wotel) | C38: =SUM('03 Flächenspiegel'!H38:H40) -> 309772.32 | D38: =SUM('03 Flächenspiegel'!H60:H62) -> 309772.32 | E38: =SUM('03 Flächenspiegel'!H82:H84) -> 309772.32 | F38: =SUM(C38:E38) -> 929316.96
B39: UG (Lager) | C39: =SUM('03 Flächenspiegel'!H41:H43) -> 69059.52 | D39: =SUM('03 Flächenspiegel'!H63:H65) -> 69059.52 | E39: =SUM('03 Flächenspiegel'!H85:H87) -> 69059.52 | F39: =SUM(C39:E39) -> 207178.56
B59: Haus | C59: Mietertrag
B60: Haus A | C60: =Mietertrag_A -> 681228.6
B61: Haus B | C61: =Mietertrag_B -> 681228.6
B62: Haus C | C62: =Mietertrag_C -> 692516.4

Sheet 02 Renditeanalyse
B2: Renditeanalyse – Brutto, Netto, EK-Rendite
B3: Auf Basis der berechneten Mieterträge und Investitionskosten. Eingaben in Blau/Gelb veränderbar.
B5: Annahmen Bewirtschaftung & Finanzierung
B6: Bewirtschaftungskosten (% v. Soll-Mietzins) | C6: 0.18 | D6: Hauswartung, Versicherung, Instandhaltung, Verwaltung
B7: Unterhalt / Erneuerung (% v. Soll-Mietzins) | C7: 0.05 | D7: Rückstellungen
B8: Eigenkapital-Anteil | C8: 0.3 | D8: 30% EK gem. Bank-Anforderung Gewerbe
B9: Fremdkapital-Zinssatz | C9: 0.025 | D9: Hypothek, aktuelles Niveau
B10: Tilgung (% v. FK p.a.) | C10: 0.01 | D10: 1% Amortisation
B13: Renditerechnung
B14: Position | C14: Etappe 1 | D14: Etappe 2 | E14: Total Projekt
B15: Soll-Mietertrag p.a. | C15: =Mietertrag_E1_Soll -> 2054973.6 | D15: =Mietertrag_E1_Soll/Hauser_E1*Hauser_E2*Miet_Faktor_E2 -> 2096073.1 | E15: =C15+D15 -> 4151046.7
B16: ./. Mietausfall | C16: =C15-Mietertrag_E1_eff -> 102748.68 | D16: =D15-(Mietertrag_E1_Soll/Hauser_E1*Hauser_E2*Miet_Faktor_E2*(1-Leerstand_E2)) -> 209607.31 | E16: =C16+D16 -> 312355.99
B17: Σ Effektiv-Mietertrag | C17: =Mietertrag_E1_eff -> 1952224.9 | D17: =Mietertrag_E1_Soll/Hauser_E1*Hauser_E2*Miet_Faktor_E2*(1-Leerstand_E2) -> 1886465.8 | E17: =C17+D17 -> 3838690.7
B18: ./. Bewirtschaftungskosten | C18: =C15*Bewirt_PCT -> 369895.25 | D18: =D15*Bewirt_PCT -> 377293.15 | E18: =C18+D18 -> 747188.4
B19: ./. Unterhalt / Erneuerung | C19: =C15*Unterhalt_PCT -> 102748.68 | D19: =D15*Unterhalt_PCT -> 104803.65 | E19: =C19+D19 -> 207552.33
B20: Σ Netto-Mietertrag (NOI) | C20: =C17-C18-C19 -> 1479581 | D20: =D17-D18-D19 -> 1404369 | E20: =C20+D20 -> 2883950
B21: Investitionskosten (Anlage) | C21: =Invest_E1 -> 37500000 | D21: =Invest_E2 -> 37500000 | E21: =C21+D21 -> 75000000
B22: Eigenkapital | C22: =C21*EK_PCT -> 11250000 | D22: =D21*EK_PCT -> 11250000 | E22: =C22+D22 -> 22500000
B23: Fremdkapital | C23: =C21*(1-EK_PCT) -> 26250000 | D23: =D21*(1-EK_PCT) -> 26250000 | E23: =C23+D23 -> 52500000
B24: FK-Zinsbelastung p.a. | C24: =C23*FK_Zins -> 656250 | D24: =D23*FK_Zins -> 656250 | E24: =C24+D24 -> 1312500
B26: Rendite-Kennzahlen
B27: Bruttorendite (Soll-Mietertrag / Invest) | C27: =C15/C21 -> 0.054799296 | D27: =D15/D21 -> 0.055895282 | E27: =E15/E21 -> 0.055347289
B28: Bruttorendite (Effektiv-Mietertrag) | C28: =C17/C21 -> 0.052059331 | D28: =D17/D21 -> 0.050305754 | E28: =E17/E21 -> 0.051182542
B29: Nettorendite (NOI / Invest) | C29: =C20/C21 -> 0.039455493 | D29: =D20/D21 -> 0.037449839 | E29: =E20/E21 -> 0.038452666
B30: Cash-on-Cash / EK-Rendite | C30: =(C20-C24)/C22 -> 0.073184977 | D30: =(D20-D24)/D22 -> 0.066499463 | E30: =(E20-E24)/E22 -> 0.06984222
B33: Sensitivitätsanalyse – Bruttorendite (Total Projekt)
B34: Variation Mietzins (Zeilen) × Variation Baukosten (Spalten)
B35: Miet / Baukosten | C35: -0.1 | D35: -0.05 | E35: 0 | F35: 0.05 | G35: 0.1
B36: -0.1 | C36: =(Mietertrag_Total_Soll*(1+$B36))/(Invest_Total*(1+C$35)) -> 0.055347289 | D36: =(Mietertrag_Total_Soll*(1+$B36))/(Invest_Total*(1+D$35)) -> 0.052434274 | E36: =(Mietertrag_Total_Soll*(1+$B36))/(Invest_Total*(1+E$35)) -> 0.04981256 | F36: =(Mietertrag_Total_Soll*(1+$B36))/(Invest_Total*(1+F$35)) -> 0.047440533 | G36: =(Mietertrag_Total_Soll*(1+$B36))/(Invest_Total*(1+G$35)) -> 0.045284146
B37: -0.05 | C37: =(Mietertrag_Total_Soll*(1+$B37))/(Invest_Total*(1+C$35)) -> 0.058422138 | D37: =(Mietertrag_Total_Soll*(1+$B37))/(Invest_Total*(1+D$35)) -> 0.055347289 | E37: =(Mietertrag_Total_Soll*(1+$B37))/(Invest_Total*(1+E$35)) -> 0.052579925 | F37: =(Mietertrag_Total_Soll*(1+$B37))/(Invest_Total*(1+F$35)) -> 0.050076119 | G37: =(Mietertrag_Total_Soll*(1+$B37))/(Invest_Total*(1+G$35)) -> 0.047799931
B38: 0 | C38: =(Mietertrag_Total_Soll*(1+$B38))/(Invest_Total*(1+C$35)) -> 0.061496988 | D38: =(Mietertrag_Total_Soll*(1+$B38))/(Invest_Total*(1+D$35)) -> 0.058260304 | E38: =(Mietertrag_Total_Soll*(1+$B38))/(Invest_Total*(1+E$35)) -> 0.055347289 | F38: =(Mietertrag_Total_Soll*(1+$B38))/(Invest_Total*(1+F$35)) -> 0.052711704 | G38: =(Mietertrag_Total_Soll*(1+$B38))/(Invest_Total*(1+G$35)) -> 0.050315717
B39: 0.05 | C39: =(Mietertrag_Total_Soll*(1+$B39))/(Invest_Total*(1+C$35)) -> 0.064571837 | D39: =(Mietertrag_Total_Soll*(1+$B39))/(Invest_Total*(1+D$35)) -> 0.061173319 | E39: =(Mietertrag_Total_Soll*(1+$B39))/(Invest_Total*(1+E$35)) -> 0.058114653 | F39: =(Mietertrag_Total_Soll*(1+$B39))/(Invest_Total*(1+F$35)) -> 0.055347289 | G39: =(Mietertrag_Total_Soll*(1+$B39))/(Invest_Total*(1+G$35)) -> 0.052831503
B40: 0.1 | C40: =(Mietertrag_Total_Soll*(1+$B40))/(Invest_Total*(1+C$35)) -> 0.067646687 | D40: =(Mietertrag_Total_Soll*(1+$B40))/(Invest_Total*(1+D$35)) -> 0.064086335 | E40: =(Mietertrag_Total_Soll*(1+$B40))/(Invest_Total*(1+E$35)) -> 0.060882018 | F40: =(Mietertrag_Total_Soll*(1+$B40))/(Invest_Total*(1+F$35)) -> 0.057982874 | G40: =(Mietertrag_Total_Soll*(1+$B40))/(Invest_Total*(1+G$35)) -> 0.055347289
B42: Lesehilfe Sensitivität
B43: • Zeile = Mietzins-Variation, Spalte = Baukosten-Variation
B44: • Wert = Bruttorendite (Soll-Mietzins / Anlagekosten). Grün = hoch, Rot = tief.
B45: • Zentralwert (gelb hinterlegt) = aktuelle Annahme.

Sheet 03 Flächenspiegel
B2: Flächenspiegel & Mietzinsmodell – Häuser A, B, C (1. Etappe)
B3: Eingaben (blau, gelb hinterlegt) sind veränderbar. Mietzinse pro m²/Jahr je Nutzung. Berechnung erfolgt automatisch.
B5: ANNAHMEN MIETZINS – Eingaben in CHF / m² / Jahr
B6: Nutzung | D6: Einheit | E6: Haus A | F6: Haus B | G6: Haus C | H6: Bemerkung
B7: EG Gewerbe – Premium (rot) | D7: CHF/m²/a | E7: 180 | F7: 180 | G7: 168 | H7: Strassenseitig, Sichtlage
B8: EG Gewerbe – Standard (gelb) | D8: CHF/m²/a | E8: 180 | F8: 180 | G8: 168 | H8: Standard-Strassenfront
B9: EG Gewerbe – Hofseite (blau) | D9: CHF/m²/a | E9: 174 | F9: 174 | G9: 168 | H9: Hofseitig, leicht reduziert
B10: EG Gewerbe – Gross (grün/lila) | D10: CHF/m²/a | E10: 168 | F10: 168 | G10: 168 | H10: Grossflächen ab 500 m²
B11: OG Büro – Premium (rot) | D11: CHF/m²/a | E11: 210 | F11: 210 | G11: 210 | H11: Eckbüros mit Aussicht
B12: OG Büro – Standard (gelb) | D12: CHF/m²/a | E12: 204 | F12: 204 | G12: 204 | H12: Standardbüros
B13: OG Büro – Standard (blau) | D13: CHF/m²/a | E13: 204 | F13: 204 | G13: 204 | H13: Standardbüros
B14: OG Büro – Standard (grün) | D14: CHF/m²/a | E14: 204 | F14: 204 | G14: 204 | H14: Standardbüros
B15: OG Gewerbe Gross (lila) | D15: CHF/m²/a | E15: 0 | F15: 0 | G15: 180 | H15: Nur Haus C
B16: OG Gewerbe Gross (orange) | D16: CHF/m²/a | E16: 0 | F16: 0 | G16: 180 | H16: Nur Haus C
B17: AT Wotel 1 – klein (rot) | D17: CHF/m²/a | E17: 480 | F17: 480 | G17: 480 | H17: Apartment-Hotel 25 m²
B18: AT Wotel 2 – medium (gelb) | D18: CHF/m²/a | E18: 456 | F18: 456 | G18: 456 | H18: Apartment-Hotel 38 m²
... B22: UG Gewerbe Lager – gross (blau) | D22: CHF/m²/a | E22: 108 | F22: 108 | G22: 108 | H22: Lager-/Werkstattfläche
B24: Mietausfall / Leerstand (Annahme alle Häuser) | E24: 0.05
B26: HAUS A – Flächenspiegel & Mietertrag (Einzelgebäude)
B27: Geschoss | C27: Nutzung | D27: Anzahl | E27: Fläche/Anz. | F27: Fläche Total | G27: Mietzins | H27: Mietertrag/a | I27: CHF/Monat | J27: Anteil | K27: Bemerkung
B28: EG | C28: Gewerbefläche 1 (rot) | D28: 1 | E28: 113.4 | F28: =D28*E28 -> 113.4 | G28: =E7 -> 180 | H28: =F28*G28 -> 20412 | I28: =H28/12 -> 1701 | J28: =IFERROR(H28/$H$44,0) -> 0.02996351
B29: EG | C29: Gewerbefläche 2 (gelb) | D29: 1 | E29: 171.22 | F29: =D29*E29 -> 171.22 | G29: =E8 -> 180 | H29: =F29*G29 -> 30819.6 | I29: =H29/12 -> 2568.3 | J29: =IFERROR(H29/$H$44,0) -> 0.045241201
B30: EG | C30: Gewerbefläche 3 (blau) | D30: 1 | E30: 228.62 | F30: =D30*E30 -> 228.62 | G30: =E9 -> 174 | H30: =F30*G30 -> 39779.88 | I30: =H30/12 -> 3314.99 | J30: =IFERROR(H30/$H$44,0) -> 0.058394319
B31: EG | C31: Gewerbefläche 4 (grün/lila) | D31: 1 | E31: 518.86 | F31: =D31*E31 -> 518.86 | G31: =E10 -> 168 | H31: =F31*G31 -> 87168.48 | I31: =H31/12 -> 7264.04 | J31: =IFERROR(H31/$H$44,0) -> 0.12795775
B32: OG | C32: Bürofläche 1 (rot) | D32: 4 | E32: 27.08 | F32: =D32*E32 -> 108.32 | G32: =E11 -> 210 | H32: =F32*G32 -> 22747.2 | I32: =H32/12 -> 1895.6 | J32: =IFERROR(H32/$H$44,0) -> 0.033391434
B33: OG | C33: Bürofläche 2 (gelb) | D33: 4 | E33: 39.73 | F33: =D33*E33 -> 158.92 | G33: =E12 -> 204 | H33: =F33*G33 -> 32419.68 | I33: =H33/12 -> 2701.64 | J33: =IFERROR(H33/$H$44,0) -> 0.047590016
B34: OG | C34: Bürofläche 3 (blau) | D34: 4 | E34: 42.03 | F34: =D34*E34 -> 168.12 | G34: =E13 -> 204 | H34: =F34*G34 -> 34296.48 | I34: =H34/12 -> 2858.04 | J34: =IFERROR(H34/$H$44,0) -> 0.050345038
B35: OG | C35: Bürofläche 4 (grün) | D35: 4 | E35: 42.59 | F35: =D35*E35 -> 170.36 | G35: =E14 -> 204 | H35: =F35*G35 -> 34753.44 | I35: =H35/12 -> 2896.12 | J35: =IFERROR(H35/$H$44,0) -> 0.051015826
B36: OG | C36: Gewerbefläche 5 (lila) | D36: 0 | E36: 0 | F36: =D36*E36 -> 0 | G36: =E15 -> 0 | H36: =F36*G36 -> 0 | I36: =H36/12 -> 0 | J36: =IFERROR(H36/$H$44,0) -> 0
B37: OG | C37: Gewerbefläche 6 (orange) | D37: 0 | E37: 0 | F37: =D37*E37 -> 0 | G37: =E16 -> 0 | H37: =F37*G37 -> 0 | I37: =H37/12 -> 0 | J37: =IFERROR(H37/$H$44,0) -> 0
B38: AT | C38: Wotel 1 – klein (rot) | D38: 12 | E38: 25.38 | F38: =D38*E38 -> 304.56 | G38: =E17 -> 480 | H38: =F38*G38 -> 146188.8 | I38: =H38/12 -> 12182.4 | J38: =IFERROR(H38/$H$44,0) -> 0.21459581
B39: AT | C39: Wotel 2 – medium (gelb) | D39: 4 | E39: 38.03 | F39: =D39*E39 -> 152.12 | G39: =E18 -> 456 | H39: =F39*G39 -> 69366.72 | I39: =H39/12 -> 5780.56 | J39: =IFERROR(H39/$H$44,0) -> 0.10182591
... B43: UG | C43: Gewerbe Lager 3 (blau) | D43: 4 | E43: 68.1 | F43: =D43*E43 -> 272.4 | G43: =E22 -> 108 | H43: =F43*G43 -> 29419.2 | I43: =H43/12 -> 2451.6 | J43: =IFERROR(H43/$H$44,0) -> 0.043185503
B44: Total Haus A | F44: =SUM(F28:F43) -> 2946.14 | H44: =SUM(H28:H43) -> 681228.6 | I44: =H44/12 -> 56769.05
B45: Mietertrag effektiv (nach Mietausfall) | H45: =H44*(1-Leerstand) -> 647167.17 | I45: =H45/12 -> 53930.598
B48: HAUS B – Flächenspiegel & Mietertrag (Einzelgebäude)
B49: Geschoss | C49: Nutzung | D49: Anzahl | E49: Fläche/Anz. | F49: Fläche Total | G49: Mietzins | H49: Mietertrag/a | I49: CHF/Monat | J49: Anteil | K49: Bemerkung
B50: EG | C50: Gewerbefläche 1 (rot) | D50: 1 | E50: 113.4 | F50: =D50*E50 -> 113.4 | G50: =F7 -> 180 | H50: =F50*G50 -> 20412 | I50: =H50/12 -> 1701 | J50: =IFERROR(H50/$H$66,0) -> 0.02996351
B51: EG | C51: Gewerbefläche 2 (gelb) | D51: 1 | E51: 171.22 | F51: =D51*E51 -> 171.22 | G51: =F8 -> 180 | H51: =F51*G51 -> 30819.6 | I51: =H51/12 -> 2568.3 | J51: =IFERROR(H51/$H$66,0) -> 0.045241201
B52: EG | C52: Gewerbefläche 3 (blau) | D52: 1 | E52: 228.62 | F52: =D52*E52 -> 228.62 | G52: =F9 -> 174 | H52: =F52*G52 -> 39779.88 | I52: =H52/12 -> 3314.99 | J52: =IFERROR(H52/$H$66,0) -> 0.058394319
...

Sheet 03b Nebenflächen-Umlage
B2: Nebenflächen-Umlage – Methode Methabau (Leubern-Referenz)
B3: Methabau verteilt Mietkosten der allgemeinen Nebenflächen (Treppenhaus, WC, Erschliessung) anteilsmässig auf die Hauptnutzflächen. Eigene Preise je Nebenflächentyp.
B5: 1. Methodenvergleich – Methabau vs. unsere bisherige Methode
B6: Kriterium | C6: Methabau (Leubern) | F6: Bisher Campus Elgg | I6: Empfehlung
B7: Flächendefinition | C7: Trennt strikt HNF (vermietbar) von allgemeinen Nebenflächen (Treppenhaus, WC, Technik); NGF = Bodenfläche ohne tragende Konstruktion | F7: Aggregiert vermietbare Flächen pro Geschoss, Nebenflächen implizit | I7: ✓ Methabau-Methode übernehmen
B8: Mietpreis Hauptnutzfläche | C8: Marktpreis CHF/m²/Jahr je Nutzung (Büro 170, Gewerbe 205-340, Wotel z.B. CHF 950/Zimmer) | F8: CHF/m²/Jahr je Geschoss × Anzahl Einheiten | I8: Beide Ansätze sind kompatibel
B9: Mietpreis Nebenflächen | C9: Eigene Preise: Treppenhaus/Erschliessung 80 CHF/m², WC 100-220 CHF/m², Technik 0 CHF/m² | F9: Keine separate Behandlung, Verteilung nur über Anzahl-Multiplikator | I9: ✓ Separate Preise je NF-Typ einführen
B10: Verteilung der Nebenflächen-Miete | C10: Anteilsmässig auf Hauptnutzflächen (Nettoflächenwert-Aufteilung) | F10: Implizit pauschal in Mietpreis HNF einkalkuliert | I10: ✓ Explizite Umlage erhöht Transparenz
B11: Transparenz für Mieter | C11: Mieter sieht klar: x CHF für HNF + y CHF Anteil Nebenflächen | F11: Mieter sieht nur Endbetrag | I11: ✓ Methabau-Methode ist marktüblicher in CH
B12: Vorteil für Investor | C12: Höhere Vermietbarkeit, klare Kalkulation, mehr Flexibilität bei Mietzinsanpassung | F12: Einfacher zu modellieren, aber weniger steuerbar | I12: ✓ Methabau-Methode empfohlen
B15: 2. Annahmen Nebenflächen-Preise (Methabau-Methode auf Campus Elgg)
B16: Nebenflächentyp | C16: Einheit | D16: CHF/m²/Jahr | E16: Anteil m² je Haus (ø) | G16: Bemerkung
B17: Treppenhaus / Erschliessungskorridor | C17: m²/Jahr | D17: 80 | E17: 187.78 | G17: Verkehrsfläche – Methabau-Standard
B18: Sanitäre Anlagen (WC H/D/IV) | C18: m²/Jahr | D18: 220 | E18: 38.46 | G18: Vom Mieter mitbenutzt
B19: Schleuse / Vorraum | C19: m²/Jahr | D19: 80 | E19: 30.9 | G19: Anteil Erschliessung
B20: Technikraum | C20: m²/Jahr | D20: 0 | E20: 30.9 | G20: Technik nicht vermietbar
B21: Lager- / Putzraum (allgemein) | C21: m²/Jahr | D21: 100 | E21: 25 | G21: Geringere Wertigkeit
B24: 3. Berechnung Mietkosten Nebenflächen pro Haus
B25: Position | D25: Fläche m² | E25: CHF/m²/Jahr | F25: Total Mietkosten/a | G25: Verteilung auf HNF | I25: Bemerkung
B26: Treppenhaus / Erschliessung | D26: 187.78 | E26: =$D$17 -> 80 | F26: =D26*E26 -> 15022.4 | G26: anteilsmässig auf HNF | I26: Pro Haus, Mittel über alle Geschosse
B27: Sanitäre Anlagen (WC) | D27: 38.46 | E27: =$D$18 -> 220 | F27: =D27*E27 -> 8461.2 | G27: anteilsmässig auf HNF | I27: Mitbenutzung Mieter
B28: Schleuse / Vorraum | D28: 30.9 | E28: =$D$19 -> 80 | F28: =D28*E28 -> 2472 | G28: anteilsmässig auf HNF | I28: Funktionsfläche
B29: Technikraum | D29: 30.9 | E29: =$D$20 -> 0 | F29: =D29*E29 -> 0 | G29: anteilsmässig auf HNF | I29: Nicht vermietet (0 CHF)
B30: Lager / Putzraum | D30: 25 | E30: =$D$21 -> 100 | F30: =D30*E30 -> 2500 | G30: anteilsmässig auf HNF | I30: Allg. Nutzung
B31: TOTAL Nebenflächen-Miete / Haus / Jahr | D31: =SUM(D26:D30) -> 313.04 | F31: =SUM(F26:F30) -> 28455.6
B33: 4. Hochrechnung Etappe 1 (3 Häuser) und Total Projekt
B34: Position | D34: Etappe 1 (3 Häuser) | F34: Etappe 2 (3 Häuser) | H34: Total Projekt | J34: Bemerkung
B35: Nebenflächen-Miete (Methabau-Methode) | D35: =NF_Miete_Haus*Hauser_E1 -> 85366.8 | F35: =NF_Miete_Haus*Hauser_E2*Miet_Faktor_E2 -> 87074.136 | H35: =D35+F35 -> 172440.94 | J35: wird auf HNF umgelegt
B36: Soll-Mietertrag HNF (bisher Modell) | D36: =Mietertrag_E1_Soll -> 2054973.6 | F36: =Mietertrag_E1_Soll/Hauser_E1*Hauser_E2*Miet_Faktor_E2 -> 2096073.1 | H36: =Mietertrag_Total_Soll -> 4151046.7 | J36: ohne Nebenflächen-Umlage
B37: Soll-Mietertrag GESAMT (mit Umlage) | D37: =D35+D36 -> 2140340.4 | F37: =F35+F36 -> 2183147.2 | H37: =H35+H36 -> 4323487.6 | J37: → neue Berechnungsbasis
B40: 5. Gegenüberstellung: Bisheriges Modell vs. Methabau-Methode (Etappe 1)
B41: Kennzahl | E41: Bisher (Modell V1) | G41: Mit Umlage (Methabau) | I41: Delta
B42: Soll-Mietertrag p.a. | E42: =Mietertrag_E1_Soll -> 2054973.6 | G42: =Mietertrag_E1_Methabau -> 2140340.4 | I42: =G42-E42 -> 85366.8
B43: Anlagekosten (BKP 0-9, Fixwert) | E43: =Invest_E1 -> 37500000 | G43: =Invest_E1 -> 37500000 | I43: =G43-E43 -> 0
B44: Bruttorendite (Soll/Invest) | E44: =Mietertrag_E1_Soll/Invest_E1 -> 0.054799296 | G44: =Mietertrag_E1_Methabau/Invest_E1 -> 0.057075744 | I44: =G44-E44 -> 0.002276448
B46: EMPFEHLUNG: Die Methabau-Methode (explizite Trennung HNF / Nebenflächen mit eigenen Preisen) ist marktüblicher und bietet höhere Transparenz für Mieter und Investoren. Sie sollte als Standard für Campus Elgg übernommen werden. Vorteile: • Mietverträge sind klarer strukturiert (Mieter sieht: x m² HNF zu CHF/m² + Anteil Nebenflächen) • Bei Mietzinsanpassungen kann differenziert vorgegangen werden • Vergleichbarkeit mit anderen Schweizer Gewerbeprojekten höher • Ergibt bei gleichen Marktpreisen einen leicht höheren Mietertrag (Mehrwert ~3-5%) Nächster Schritt: Im 03 Flächenspiegel die Nebenflächen-Preise separat einsetzen und in 03b die Verteilung definieren.

Sheet 04 Gebäudekennzahlen
B2: Gebäudekennzahlen – Flächen, Volumen, Nutzungsverteilung
B3: Übersicht GF (Geschossfläche), GV (Geschossvolumen), HNF (Hauptnutzfläche). Werte aus Quelldaten (Tetris/Skyline Architekten).
B5: 1. Gebäudekennwerte pro Haus (1. Etappe – 1 Gebäude je Haus)
B6: Kennwert | C6: Einheit | D6: Haus A | E6: Haus B | F6: Haus C | G6: Total E1 (3 Häuser) | H6: Ø pro Haus | J6: Bemerkung
B7: Geschossfläche oi (Total) | C7: m² | D7: 3600.37 | E7: 3600.37 | F7: 3600.37 | G7: =D7+E7+F7 -> 10801.11 | H7: =G7/3 -> 3600.37 | J7: EG+OG+AT+DA
B8: Geschossfläche ui (Total) | C8: m² | D8: 1210.17 | E8: 1210.17 | F8: 1210.17 | G8: =D8+E8+F8 -> 3630.51 | H8: =G8/3 -> 1210.17 | J8: UG + FU
B9: Geschossfläche oi+ui (gesamt) | C9: m² | D9: 1568.46 | E9: 1568.46 | F9: 1568.46 | G9: =D9+E9+F9 -> 4705.38 | H9: =G9/3 -> 1568.46 | J9: GF Total Quelldaten / 3
B10: Geschossvolumen oi | C10: m³ | D10: 13061.22 | E10: 13061.22 | F10: 13061.22 | G10: =D10+E10+F10 -> 39183.66 | H10: =G10/3 -> 13061.22 | J10: Volumen oberirdisch
B11: Geschossvolumen ui | C11: m³ | D11: 4594.31 | E11: 4594.31 | F11: 4594.31 | G11: =D11+E11+F11 -> 13782.93 | H11: =G11/3 -> 4594.31 | J11: Volumen unterirdisch
B12: Geschossvolumen Total (GV) | C12: m³ | D12: 17655.53 | E12: 17655.53 | F12: 17655.53 | G12: =D12+E12+F12 -> 52966.59 | H12: =G12/3 -> 17655.53 | J12: Massgeblich für Kostenschätzung
B13: Werkleitungskulisse | C13: m² | D13: 73.63 | E13: 73.63 | F13: 73.63 | G13: =D13+E13+F13 -> 220.89 | H13: =G13/3 -> 73.63 | J13: Anteilig
B14: Vermietbare Fläche oi (HNF) | C14: m² | D14: 2306.7 | E14: 2306.7 | F14: 2438.42 | G14: =D14+E14+F14 -> 7051.82 | H14: =G14/3 -> 2350.6067 | J14: ohne Sitzungs-/Gemeinschaftsr.
B15: Vermietbare Fläche oi (mit Allg.) | C15: m² | D15: 2603.78 | E15: 2603.78 | F15: 2661.9 | G15: =D15+E15+F15 -> 7869.46 | H15: =G15/3 -> 2623.1533 | J15: mit allgemeinen Räumen
B16: Anzahl Geschosse (oi) | C16: Stk | D16: 4 | E16: 4 | F16: 4 | G16: =D16+E16+F16 -> 12 | H16: =G16/3 -> 4 | J16: EG, OG, AT, DA
B17: Anzahl Geschosse (ui) | C17: Stk | D17: 2 | E17: 2 | F17: 2 | G17: =D17+E17+F17 -> 6 | H17: =G17/3 -> 2 | J17: UG, FU
B20: 2. Flächenverteilung nach Nutzungstyp (Total Etappe 1)
B21: Nutzungstyp | C21: Beschreibung | F21: Fläche m² | G21: Anteil
B22: HNF | C22: Hauptnutzfläche (vermietbar) | F22: 7051.82 | G22: =F22/$F$27 -> 0.52983517
B23: NNF | C23: Nebennutzfläche (UG-Lager, WK, Nasszellen) | F23: 1918.32 | G23: =F23/$F$27 -> 0.14413207
B24: VF | C24: Verkehrsfläche (intern + aussen) | F24: 2351.79 | G24: =F24/$F$27 -> 0.17670063
B25: FF | C25: Funktionsfläche (Technik) | F25: 92.7 | G25: =F25/$F$27 -> 0.0069649708
B26: KF | C26: Konstruktionsfläche | F26: 1894.83 | G26: =F26/$F$27 -> 0.14236716
B27: Total | F27: =SUM(F22:F26) -> 13309.46 | G27: 1

Sheet 05 Kostenschätzung
B2: Kostenschätzung – Anlagekosten BKP (Fixwerte gem. KV März 2026)
B3: Werte gemäss Kostenvoranschlag Campus Elgg, Stand März 2026. BKP 0 (Grundstück) und alle weiteren Positionen sind fix vorgegeben.
B5: BKP-Übersicht Etappe 1 / Etappe 2 / Total
B6: BKP | C6: Bezeichnung | D6: Etappe 1 | E6: Etappe 2 | F6: Total | G6: Anteil | H6: Bemerkung
B7: BKP 0 | C7: Grundstückskosten | D7: 7500000 | E7: 7500000 | F7: =D7+E7 -> 15000000 | G7: =F7/$F$17 -> 0.2 | H7: Inkl. Erwerbsnebenkosten
B8: BKP 1 | C8: Vorbereitungsarbeiten | D8: 3750000 | E8: 3750000 | F8: =D8+E8 -> 7500000 | G8: =F8/$F$17 -> 0.1 | H8: Abbruch, Aushub, Werkleitungen
B9: BKP 2 | C9: Gebäudekosten | D9: 22800000 | E9: 22800000 | F9: =D9+E9 -> 45600000 | G9: =F9/$F$17 -> 0.608 | H9: Massgeblicher Kostenblock
B10: BKP 3 | C10: Honorare GU Tiefbau | D10: 350000 | E10: 350000 | F10: =D10+E10 -> 700000 | G10: =F10/$F$17 -> 0.0093333333
B11: BKP 4 | C11: Betriebseinrichtungen | D11: 0 | E11: 0 | F11: =D11+E11 -> 0 | G11: =F11/$F$17 -> 0 | H11: Nicht budgetiert
B12: BKP 5 | C12: Baunebenkosten | D12: 1300000 | E12: 1300000 | F12: =D12+E12 -> 2600000 | G12: =F12/$F$17 -> 0.034666667 | H12: Bewilligungen, Versicherungen
B13: BKP 6 | C13: Reserve (nicht budgetiert) | D13: 0 | E13: 0 | F13: =D13+E13 -> 0 | G13: =F13/$F$17 -> 0 | H13: Reserve nicht eingestellt
B14: BKP 7 | C14: Ausstattung (nicht budgetiert) | D14: 0 | E14: 0 | F14: =D14+E14 -> 0 | G14: =F14/$F$17 -> 0 | H14: Wird durch Mieter erstellt
B15: BKP 8 | C15: Verkauf & Vermarktung | D15: 460000 | E15: 460000 | F15: =D15+E15 -> 920000 | G15: =F15/$F$17 -> 0.012266667 | H15: Marketing, Vermarktung
B16: BKP 9 | C16: Bauherrenkosten | D16: 1340000 | E16: 1340000 | F16: =D16+E16 -> 2680000 | G16: =F16/$F$17 -> 0.035733333 | H16: PM, Projektsteuerung
C17: TOTAL ANLAGEKOSTEN | D17: =SUM(D7:D16) -> 37500000 | E17: =SUM(E7:E16) -> 37500000 | F17: =SUM(F7:F16) -> 75000000 | G17: 1
B19: Finanzierungsstruktur (gem. KV)
B20: Eigenkapital | D20: 14500000 | E20: 14500000 | F20: =D20+E20 -> 29000000 | H20: 29 Mio. Total
B21: Fremdkapital | D21: 23000000 | E21: 23000000 | F21: =D21+E21 -> 46000000 | H21: 46 Mio. Total
B22: EK-Quote (berechnet) | D22: =D20/(D20+D21) -> 0.38666667 | E22: =E20/(E20+E21) -> 0.38666667 | F22: =F20/(F20+F21) -> 0.38666667
B25: Landwert-Sicht: BKP-Reklassifikation für Investorenargumentation
B26: Argumentation: 80% der Vorbereitungsarbeiten (BKP 1) sind Quartierplan-, Erschliessungs- und Entwicklungskosten – wirtschaftlich Teil des Landwerts. Wir leiten diese rechnerisch zu BKP 0 um, um den effektiven Landwert pro m² zu zeigen.
B28: Position | D28: Etappe 1 | E28: Etappe 2 | F28: Total | H28: Bemerkung
B29: Umlagerungs-Quote BKP 1 → BKP 0 | D29: 0.8 | H29: Anteil Quartierplan / Erschliessung
B31: BKP 0 ursprünglich (KV) | D31: ='05 Kostenschätzung'!$D$7 -> 7500000 | E31: ='05 Kostenschätzung'!$E$7 -> 7500000 | F31: =D31+E31 -> 15000000
B32: BKP 1 ursprünglich (KV) | D32: ='05 Kostenschätzung'!$D$8 -> 3750000 | E32: ='05 Kostenschätzung'!$E$8 -> 3750000 | F32: =D32+E32 -> 7500000
B33: Umlagerung (80% von BKP 1) | D33: =D32*Landwert_Quote -> 3000000 | E33: =E32*Landwert_Quote -> 3000000 | F33: =D33+E33 -> 6000000
B34: BKP 0 NEU (effektiver Landwert) | D34: =D31+D33 -> 10500000 | E34: =E31+E33 -> 10500000 | F34: =D34+E34 -> 21000000
B35: BKP 1 NEU (reine Bauvorbereitung) | D35: =D32-D33 -> 750000 | E35: =E32-E33 -> 750000 | F35: =D35+E35 -> 1500000
B37: Impliziter Landwert pro m² (effektiv) | D37: =Landwert_eff_E1/GS_E1 -> 923.45767 | E37: =Landwert_eff_E2/GS_E2 -> 780.04974 | F37: =Landwert_eff_Total/GS_Total -> 845.71739 | H37: Marktnah CHF 650-800/m² Region Winterthur

Sheet 06 Etappe 2
B2: Etappenplanung – Etappe 1, Etappe 2, Gesamtprojekt
B3: Etappe 2 = 3 weitere Häuser (Verdoppelung). Annahmen für Skalierung sind veränderbar (Baukosten-Indexierung, Mietzins-Steigerung).
B5: Annahmen Skalierung Etappe 2
B6: Anzahl Häuser Etappe 1 | E6: 3 | G6: Häuser A, B, C
B7: Anzahl Häuser Etappe 2 | E7: 3 | G7: 3 weitere Gebäude (z.B. D, E, F)
B8: Baukosten-Faktor Etappe 2 | E8: 1.04 | G8: Indexierung gegenüber E1 (z.B. +4%)
B9: Mietzins-Faktor Etappe 2 | E9: 1.02 | G9: Annahme Mietzinssteigerung (z.B. +2%)
B10: Leerstand Etappe 2 (Anlauf) | E10: 0.1 | G10: Höhere Anlaufquote – Vermietung beginnt
B13: Zusammenstellung Etappe 1 / Etappe 2 / Total
B14: Kennzahl | C14: Einheit | D14: Etappe 1 | E14: Etappe 2 | F14: Total Projekt | H14: Bemerkung
B15: Anzahl Häuser | C15: Stk | D15: =Hauser_E1 -> 3 | E15: =Hauser_E2 -> 3 | F15: =D15+E15 -> 6
B16: Geschossvolumen GV | C16: m³ | D16: =GV_E1_Total -> 52966.59 | E16: =GV_E1_Total/Hauser_E1*Hauser_E2 -> 52966.59 | F16: =D16+E16 -> 105933.18 | H16: Annahme: gleiche Bauweise
B17: Geschossfläche GF | C17: m² | D17: =GF_E1_Total -> 4705.38 | E17: =GF_E1_Total/Hauser_E1*Hauser_E2 -> 4705.38 | F17: =D17+E17 -> 9410.76
B18: Hauptnutzfläche HNF (vermietbar) | C18: m² | D18: =HNF_E1_Total -> 7051.82 | E18: =HNF_E1_Total/Hauser_E1*Hauser_E2 -> 7051.82 | F18: =D18+E18 -> 14103.64
B19: Soll-Mietertrag p.a. | C19: CHF | D19: =Mietertrag_E1_Soll -> 2054973.6 | E19: =Mietertrag_E1_Soll/Hauser_E1*Hauser_E2*Miet_Faktor_E2 -> 2096073.1 | F19: =D19+E19 -> 4151046.7 | H19: E2 indexiert
B20: Effektiv-Mietertrag p.a. | C20: CHF | D20: =Mietertrag_E1_eff -> 1952224.9 | E20: =Mietertrag_E1_Soll/Hauser_E1*Hauser_E2*Miet_Faktor_E2*(1-Leerstand_E2) -> 1886465.8 | F20: =D20+E20 -> 3838690.7 | H20: E1 mit 5%, E2 mit Anlauf-Leerstand
B21: Anlagekosten (Investitionskosten) | C21: CHF | D21: =Invest_E1 -> 37500000 | E21: =Invest_E1/Hauser_E1*Hauser_E2*BK_Faktor_E2 -> 39000000 | F21: =D21+E21 -> 76500000 | H21: E2 indexiert

Sheet 07 Grundstück
B2: Grundstück – Parzellen, Flächen, Landwerte (Katasterplan März 2026)
B3: Grundstücksdaten aus dem Katasterplan 010 (Tetris AG / Urbanstreet AG). Liegenschaften: Obermühle, 8353 Elgg.
B5: 1. Parzellenstruktur Etappe 1 und Etappe 2
B6: Position | C6: Einheit | D6: Etappe 1 | E6: Etappe 2 | F6: Total | G6: Bemerkung
B7: Teilfläche Bauland Nord | C7: m² | D7: 6412.64 | F7: =D7 -> 6412.64 | G7: Hauptbauland E1
B8: Teilfläche Bauland Süd | C8: m² | D8: 4957.67 | F8: =D8 -> 4957.67 | G8: Erweiterung E1
B9: Subtotal Bauland | C9: m² | D9: =D7+D8 -> 11370.31 | F9: =D9+E9 -> 11370.31 | G9: Summe Bauland
B10: Landwirtschaftsland (nur E1) | C10: m² | D10: 2255.87 | F10: =D10 -> 2255.87 | G10: Nicht bebaubar
B11: Bauland Etappe 2 | C11: m² | E11: 13460.68 | F11: =E11 -> 13460.68 | G11: Ostseite Obermühle
B12: TOTAL Grundstücksfläche Bauland | C12: m² | D12: =D9 -> 11370.31 | E12: =E11 -> 13460.68 | F12: =D12+E12 -> 24830.99 | G12: Nur bebaubares Land
B15: 2. Landwert-Berechnung
B16: Position | C16: Einheit | D16: Etappe 1 | E16: Etappe 2 | F16: Total | G16: Bemerkung
B17: Bauland-Fläche | C17: m² | D17: =GS_E1 -> 11370.31 | E17: =GS_E2 -> 13460.68 | F17: =GS_Total -> 24830.99 | G17: Bauland gem. Katasterplan
B18: BKP 0 Grundstückskosten (KV) | C18: CHF | D18: =VLOOKUP("BKP 0",'05 Kostenschätzung'!$B$7:$F$16,3,FALSE()) -> 7500000 | E18: =VLOOKUP("BKP 0",'05 Kostenschätzung'!$B$7:$F$16,4,FALSE()) -> 7500000 | F18: =D18+E18 -> 15000000 | G18: Aus KV-Tabelle BKP 0
B19: Impliziter Landwert pro m² | C19: CHF/m² | D19: =D18/D17 -> 659.61262 | E19: =E18/E17 -> 557.17839 | F19: =F18/F17 -> 604.08385 | G19: Plausibilitätscheck Marktpreis
B20: Marktreferenz Landwert (zu validieren) | C20: CHF/m² | D20: 650 | E20: 700 | F20: =(D20*D17+E20*E17)/F17 -> 677.1046 | G20: Region Winterthur Gewerbezone
B23: 3. Ausnützung und Bebaubarkeit
B24: Ausnützungsziffer (AZ) Gewerbezone | C24: — | D24: 0.8 | E24: 0.8 | G24: Annahme BZO Elgg, zu validieren
B25: Realisierte GF (E1) | C25: m² | D25: =GF_E1_Total -> 4705.38 | E25: =GF_E1_Total/Hauser_E1*Hauser_E2 -> 4705.38 | F25: =D25+E25 -> 9410.76 | G25: Aus 04 Gebäudekennzahlen
B26: Theor. max. anrechenbare GF (= AZ × Grundstück) | C26: m² | D26: =GS_E1*D24 -> 9096.248 | E26: =GS_E2*E24 -> 10768.544 | F26: =D26+E26 -> 19864.792 | G26: Bauland × AZ
B27: Auslastungsgrad | C27: % | D27: =IFERROR(D25/D26,0) -> 0.51728801 | E27: =IFERROR(E25/E26,0) -> 0.43695601 | F27: =IFERROR(F25/F26,0) -> 0.47374068 | G27: Realisierte GF / max. GF
B30: FLÄCHEN-CHECK aus Katasterplan 010 (Stand 09.03.2026): • Etappe 1 Bauland: 11'370.31 m² (6'412.64 + 4'957.67) + 2'255.87 m² Landwirtschaftsland • Etappe 2 Bauland: 13'460.68 m² (Ostseite Obermühle) • Total Bauland: 24'830.99 m² – impliziter Landwert aus BKP 0 = CHF 604/m² Plausibilitätscheck: Marktreferenz Region Winterthur Gewerbezone CHF 650-800/m² – KV-Wert im unteren Bereich.

Sheet 08 Quelldaten
A1: Quelldaten – Original aus DEV_02_Campursus_TCO_Zin_InvestorenMemo.xlsx, Reiter «Projektdaten»
A2: Diese Daten sind die Berechnungsgrundlage. Nicht überschreiben – sie dienen der Nachvollziehbarkeit. Berechnungen erfolgen in den anderen Reitern.
A4: Campus Elgg
A5: Flächen und Volumen | B5: *Kopie Vermarktung für TCO im Tetris AG Ablage" | G5: 1. Etappe | J5: 1. + 2. Etappe
A6: 1 Gewerbehaus | G6: 3 | H6: Gewerbehäuser | J6: 6 | K6: Gewerbehäuser
A7: Geschoss oi | B7: Nutzung | C7: GF m² | D7: GH m | E7: GV m³ | G7: GF m² | H7: GV m³ | J7: GF m² | K7: GV m³
A8: Total | C8: 3495.12 | E8: 13061.223 | G8: 10485.36 | H8: 39183.668 | J8: 20970.72 | K8: 78367.336
A9: EG | B9: Gewerbe | C9: 1192.21 | D9: 4.8 | E9: 5722.608 | G9: 3576.63 | H9: 17167.824 | J9: 7153.26 | K9: 34335.648
B10: Eingang Ost/West | C10: 13.51 | D10: 2.74 | E10: 37.0174 | G10: 40.53 | H10: 111.0522 | J10: 81.06 | K10: 222.1044
A11: OG | B11: Büro | C11: 1086.96 | D11: 2.57 | E11: 2793.4872 | G11: 3260.88 | H11: 8380.4616 | J11: 6521.76 | K11: 16760.923
A12: AT | B12: Wotel | C12: 1179.36 | D12: 3.8 | E12: 4481.568 | G12: 3538.08 | H12: 13444.704 | J12: 7076.16 | K12: 26889.408
A13: DA | B13: Liftüberfahrt Ost/West | C13: 23.08 | D13: 1.15 | E13: 26.542 | G13: 69.24 | H13: 79.626 | J13: 138.48 | K13: 159.252
A14: Geschoss ui | B14: Nutzung | C14: GF m² | D14: GH m | E14: GV m³ | G14: GF m² | H14: GV m³ | J14: GF m² | K14: GV m³
A15: Total | C15: 1210.17 | E15: 4594.3092 | G15: 3630.51 | H15: 13782.928 | J15: 7261.02 | K15: 27565.855
A16: UG | B16: Gewerbe | C16: 1187.63 | D16: 3.84 | E16: 4560.4992 | G16: 3562.89 | H16: 13681.498 | J16: 7125.78 | K16: 27362.995
A17: FU | B17: Liftunterfahrt Ost/West | C17: 22.54 | D17: 1.5 | E17: 33.81 | G17: 67.62 | H17: 101.43 | J17: 135.24 | K17: 202.86
A18: Geschoss oi+ui | C18: GF m² | E18: GV m³ | G18: GF m² | H18: GV m³ | J18: GF m² | K18: GV m³
A19: Total | C19: 4705.29 | E19: 17655.532 | G19: 14115.87 | H19: 52966.595 | J19: 28231.74 | K19: 105933.19
A20: Total Werkleitungskulisse | G20: 220.89 | H20: 905.52 | J20: 552.89 | K20: 2277.695
A22: A+B+C | B22: Total vermietbare Fläche oi | F22: 7051.82 | G22: ohne Sitzungsräume im OG und Gemeinschaftsräume im AT, mit diesen > | L22: 7869.46 | M22: CAD sup > | N22: 7820.91 | O22: (o. Stützen) | P22: 0.99383058
A23: Haus A
B24: Total vermietbare Fläche oi | F24: 2306.7 | G24: ohne Sitzungsräume im OG und Gemeinschaftsräume im AT, mit diesen > | L24: 2603.78 | M24: CAD sup > | N24: 2587.59 | O24: (o. Stützen) | P24: 0.99378212
A25: Geschoss | B25: Nutzung | C25: Anzahl | D25: Flächentyp | E25: Fläche/Anz. m² | F25: Fläche/Total m² | G25: Anteil GF/Anz | H25: Anteil GF/Total | I25: Anteil UG/Anz | J25: Anteil UG/Total | K25: Inkl. Alles/Anz | L25: Inkl. Alles/Total | M25: % Aufschlag | N25: CHF/m² | Q25: CHF/a/Total | R25: CHF/m/Total | S25: Total EG
A26: EG | B26: Gewerbefläche 1 (rot) | C26: 1 | D26: HNF | F26: 113.4 | H26: 19.076163 | J26: 27.298045 | L26: 159.77421 | M26: 1.4089436 | N26: 150 | Q26: 23966.131 | R26: 1997.1776
A27: 1205.72 | B27: Gewerbefläche 2 (gelb) | C27: 1 | D27: HNF | F27: 171.22 | H27: 28.802651 | J27: 41.216678 | L27: 241.23933 | M27: 1.4089436 | N27: 150 | Q27: 36185.899 | R27: 3015.4916
B28: Gewerbefläche 3 (blau) | C28: 1 | D28: HNF | F28: 228.62 | H28: 38.458487 | J28: 55.034207 | L28: 322.11269 | M28: 1.4089436 | N28: 145 | Q28: 46706.341 | R28: 3892.195
B29: Gwerbefläche 4 (grün) | C29: 1 | D29: HNF | F29: 518.86 | H29: 87.282699 | J29: 124.9018 | L29: 731.04449 | M29: 1.4089436 | N29: 140 | Q29: 102346.23 | R29: 8528.8524
B30: Verkehrsfläche (grau) | D30: VF | F30: 82.12 | S30: 209204.6
B31: Konstruktionsfläche | D31: KF | F31: 91.5
B33: Total vermietbare Fläche | F33: 1032.1
B34: Allg. Flächen zu verteilen | F34: 173.62 | J34: 248.45073
A35: Geschoss | B35: Nutzung | C35: Anzahl | D35: Flächentyp | E35: Fläche/Anz. m² | F35: Fläche/Total m² | G35: Anteil GF/Anz | H35: Anteil GF/Total | I35: Anteil UG/Anz | J35: Anteil UG/Total | K35: Inkl. Alles/Anz | L35: Inkl. Alles/Total | M35: % Aufschlag | N35: CHF/m² | O35: CHF/a/Anz | P35: CHF/m/Anz | Q35: CHF/a/Total | R35: CHF/m/Total | S35: Total OG
A36: OG | B36: Bürofläche 1 (rot) | C36: 4 | D36: HNF | E36: 27.08 | F36: 108.32 | G36: 26.220282 | H36: 104.88113 | I36: 6.5187924 | J36: 26.07517 | K36: 59.819074 | L36: 239.2763 | M36: 2.2089762 | N36: 175 | O36: 10468.338 | P36: 872.3615 | Q36: 41873.352 | R36: 3489.446
A37: 1192.21 | B37: Bürofläche 2 (gelb) | C37: 4 | D37: HNF | E37: 39.73 | F37: 158.92 | G37: 38.468678 | H37: 153.87471 | I37: 9.5639447 | J37: 38.255779 | K37: 87.762623 | L37: 351.05049 | M37: 2.2089762 | N37: 170 | O37: 14919.646 | P37: 1243.3038 | Q37: 59678.584 | R37: 4973.2153
A38: (Ohne Terrasse = | B38: Bürofläche 3 (blau) | C38: 4 | D38: HNF | E38: 42.03 | F38: 168.12 | G38: 40.695659 | H38: 162.78264 | I38: 10.117609 | J38: 40.470435 | K38: 92.843268 | L38: 371.37307 | M38: 2.2089762 | N38: 170 | O38: 15783.356 | P38: 1315.2796 | Q38: 63133.422 | R38: 5261.1185
B39: Bürofläche 4 (grün) | C39: 4 | D39: HNF | E39: 42.59 | F39: 170.36 | G39: 41.237881 | H39: 164.95152 | I39: 10.252414 | J39: 41.009656 | K39: 94.080295 | L39: 376.32118 | M39: 2.2089762 | N39: 170 | O39: 15993.65 | P39: 1332.8042 | Q39: 63974.6 | R39: 5331.2167
B40: Sitzungszimmer/Räume | C40: 4 | D40: HNF | E40: 36.8 | F40: 147.2 | S40: 228659.96
B41: Verkehrsfläche (grau) | D41: VF | F41: 204.62
B42: Aussenverkehrsfläche (grau) | D42: AVF | F42: 105.25
B43: Konstruktionsfläche | D43: KF | F43: 129.42
...

Sheet 09 Prozess & Next Steps
B2: Prozess-Dokumentation & nächste Schritte
B3: Vorgehen, getroffene Annahmen, offene Punkte – als Grundlage für VR-Sitzung und Investorengespräche.
B5: 1. Modellaufbau & Datenherkunft
B6: 1. Datenquelle | C6: DEV_02_Campursus_TCO_Zin_InvestorenMemo.xlsx | D6: Quelldatei Tetris AG – komplett in 08 Quelldaten gespiegelt
B7: 2. Flächendaten | C7: Geschossflächen oi/ui, Volumen, vermietbare Flächen | D7: Pro Geschoss EG/OG/AT/UG pro Haus extrahiert
B8: 3. Mietzinsannahmen | C8: EG: 140–150 CHF/m², OG: 170–175, AT (Wotel): 370–400, UG: 90 | D8: Werte aus Quelldaten übernommen – pro Haus separat veränderbar
B9: 4. Leerstand | C9: 5% (E1) / 10% Anlauf (E2) | D9: Marktüblich für gewerbliche Vermietung
B10: 5. Baukostenstruktur | C10: BKP 0–9 (Schweizer Baukostenplan) | D10: BKP 2 (Gebäude) als Kernblock CHF/m³ GV – marktübliche Kennwerte
B11: 6. Etappierung | C11: E1 = 3 Häuser (A,B,C), E2 = 3 weitere | D11: Skalierungsfaktoren Baukosten +4%, Mietzins +2% (anpassbar)
B12: 7. Rendite-Modell | C12: Brutto, Netto (nach Bewirtschaftung), EK-Rendite (nach FK-Zins) | D12: Sensitivitätsanalyse Miet vs. Baukosten ±10%
B14: 2. Offene Punkte – Daten zu liefern
B15: 1. Grundstücksdaten | C15: Fläche E1, Fläche E2, Parzellennummer | D15: Bitte aus BG Elgg / Sondernutzungsplan beibringen
B16: 2. Ausnützungsziffer (AZ) | C16: Aus BZO Elgg | D16: Definiert maximale GF – kritisch für Etappe 2
B17: 3. Landwert pro m² | C17: Marktreferenzen Region Winterthur/Elgg | D17: Bewertung durch Schätzer oder Vergleichswerte
B18: 4. BKP 2 Validierung | C18: CHF/m³ GV: aktuell 720 CHF/m³ als Annahme | D18: Submissionsofferten oder TU-Richtpreise einholen
B19: 5. Finanzierungsstruktur | C19: EK-Quote, Hypothek, Tilgungsplan | D19: Mit Hausbank klären – aktuell 30% EK / 2.5% Zins angesetzt
B20: 6. Mietzins-Validierung | C20: Gewerbe 140–150 CHF/m², Wotel 370–400 CHF/m² | D20: Vergleich mit aktuellen Mietspiegeln Region Winterthur
B21: 7. Vermarktungskonzept | C21: Mietermix, Vorvermietungsquote | D21: Targets für Pre-Letting definieren
B23: 3. Empfohlene nächste Schritte
B24: 1. Kurzfristig (1–2 Wochen) | C24: Grundstücksdaten in 07 Grundstück eintragen; BKP 0 (Land) wird in 05 Kostenschätzung übernommen | D24: Verantwortlich: VR / Projektleitung
B25: 2. Mittelfristig (Monat) | C25: Marktcheck Mietzinse mit Maklern (Wüest Partner, IAZI) – Validierung der CHF/m² Annahmen | D25: Anschliessend Sensitivität neu durchrechnen
B26: 3. Vor VR-Sitzung | C26: Cockpit (Reiter 01) als One-Pager für Investoren extrahieren – Export als PDF | D26: Renditeanalyse mit drei Szenarien (Base/Best/Worst Case) versehen
B27: 4. Vor Finanzierungsverhandlung | C27: Mit Hausbank Term Sheet besprechen, EK-Quote validieren | D27: DSCR (Debt Service Coverage Ratio) ergänzen falls gewünscht
B28: 5. Vor Baubeschluss | C28: Submissionen für BKP 2 (Gebäude) einholen – Validierung CHF/m³ GV | D28: Kostengarantie mit TU / GU prüfen
B29: 6. Etappe 2 Entscheid | C29: Auslastungsgrad Etappe 1 nach 12 Monaten messen → Entscheid Etappe 2 | D29: Trigger-Punkte definieren (z.B. > 80% Vermietung)
B31: 4. Methodische Hinweise
B32: • Alle Werte sind über benannte Bereiche (Defined Names) verlinkt – Änderung im Flächenspiegel oder Kostenschätzung wirkt automatisch auf Cockpit und Rendite.
B33: • Farbcodes (Blau/Schwarz/Grün) nach Industriestandard Financial Modelling.
B34: • Mietzinse pro Haus separat veränderbar – ermöglicht Differenzierung nach Lage und Mieterprofil.
B35: • Quelldatenreiter unverändert – Audit-Trail jederzeit gewährleistet.
B36: • Sensitivitätsanalyse mit ±10% Variation auf Mietzins und Baukosten – zeigt Bandbreite der Rendite.
B37: • Etappe 2 ist parametrisch modelliert – Indexierungs- und Anlauf-Annahmen explizit.
B38: • Bei strukturellen Änderungen (Mieterbestand, Nutzungsmix): am besten 03 Flächenspiegel anpassen – alle Folgereiter rechnen nach.

Sheet 10 Ziel-Abgleich
B2: Ziel-Abgleich: Modell vs. KV Campus Elgg (März 2026)
B3: Vergleich der aktuell modellierten Renditen mit den Sollwerten aus dem Kostenvoranschlag. Zeigt auf, wo Anpassungen am Mietzins-Modell nötig sind, um die 6.37% Bruttorendite zu erreichen.
B5: 1. Sollwerte gemäss Kostenvoranschlag März 2026
B6: Position | C6: Etappe 1 | D6: Etappe 2 | E6: Total Projekt | F6: Quelle
B7: Anlagekosten (BKP 0-9) | C7: 37500000 | D7: 37500000 | E7: =C7+D7 -> 75000000 | F7: KV März 2026
B8: Mietertrag p.a. (Soll) | C8: 2388141 | D8: 2388141 | E8: =C8+D8 -> 4776282 | F8: KV März 2026
B9: Kapitalisierter Wert | C9: 47762813 | D9: 47762813 | E9: =C9+D9 -> 95525626 | F9: Bei 5.00% Kap.-Satz
B10: Kapitalisierungssatz | C10: 0.05 | D10: 0.05 | E10: 0.05 | F10: Annahme KV
B11: Bruttorendite (Soll) | C11: 0.0637 | D11: 0.0637 | E11: 0.0637 | F11: KV-Vorgabe
B12: Nettorendite (Soll) | C12: 0.0573 | D12: 0.0573 | E12: 0.0573 | F12: KV-Vorgabe
B15: 2. Aktuelle Modell-Werte (verlinkt)
B16: Position | C16: Etappe 1 | D16: Etappe 2 | E16: Total | F16: Bemerkung
B17: Anlagekosten Modell | C17: =Invest_E1 -> 37500000 | D17: =Invest_E2 -> 37500000 | E17: =Invest_Total -> 75000000 | F17: Aus 05 Kostenschätzung
B18: Soll-Mietertrag p.a. Modell | C18: =Mietertrag_E1_Soll -> 2054973.6 | D18: =Mietertrag_Total_Soll-Mietertrag_E1_Soll -> 2096073.1 | E18: =Mietertrag_Total_Soll -> 4151046.7 | F18: Ohne Nebenflächen-Umlage
B19: Soll-Miete Methabau | C19: =Mietertrag_E1_Methabau -> 2140340.4 | D19: =Mietertrag_E2_Methabau -> 2183147.2 | E19: =Mietertrag_Total_Methabau -> 4323487.6 | F19: Mit Nebenflächen-Umlage
B20: Bruttorendite Modell | C20: =Mietertrag_E1_Soll/Invest_E1 -> 0.054799296 | D20: =Mietertrag_E1_Soll/Invest_E1 -> 0.054799296 | E20: =Mietertrag_Total_Soll/Invest_Total -> 0.055347289 | F20: Modell-Output
B21: Nettorendite Modell | C21: =NettoRendite_E1 -> 0.039455493 | D21: =NettoRendite_E1 -> 0.039455493 | E21: =NettoRendite_Total -> 0.038452666 | F21: Aus 02 Renditeanalyse
B24: 3. Delta-Analyse – Wo ist die Lücke?
B25: Kennzahl | C25: Soll (KV) | D25: Modell V1 | E25: Δ absolut | F25: Δ relativ | G25: Diagnose
B26: Anlagekosten Etappe 1 | C26: =C7 -> 37500000 | D26: =C17 -> 37500000 | E26: =D26-C26 -> 0 | F26: =IFERROR((D26-C26)/C26,0) -> 0 | G26: Diff. zu 0 → Baukosten stimmen mit KV
B27: Mietertrag Etappe 1 p.a. | C27: =C8 -> 2388141 | D27: =C18 -> 2054973.6 | E27: =D27-C27 -> -333167.4 | F27: =IFERROR((D27-C27)/C27,0) -> -0.1395091 | G27: Lücke wird durch Mietzins-Anpassung geschlossen
B28: Bruttorendite Etappe 1 | C28: =C11 -> 0.0637 | D28: =C20 -> 0.054799296 | E28: =D28-C28 -> -0.008900704 | F28: =IFERROR((D28-C28)/C28,0) -> -0.13972848 | G28: Folgt aus Mietertrag-Lücke
B29: Nettorendite Etappe 1 | C29: =C12 -> 0.0573 | D29: =C21 -> 0.039455493 | E29: =D29-C29 -> -0.017844507 | F29: =IFERROR((D29-C29)/C29,0) -> -0.31142246 | G29: Folgt aus Mietertrag und Bewirtschaftungskosten
B32: 4. Was wäre nötig, um die Bruttorendite 6.37% zu erreichen?
B33: Nötiger Soll-Mietertrag p.a. (E1) | C33: =C11*C17 -> 2388750 | D33: Ziel-Brutto × Anlagekosten
B34: Aktueller modellierter Mietertrag (E1) | C34: =C18 -> 2054973.6 | D34: Aus 03 Flächenspiegel
B35: Differenz zu schliessen | C35: =C33-C34 -> 333776.4 | D35: CHF/Jahr Mehrertrag nötig
B36: Aktuelle HNF Etappe 1 | C36: =HNF_E1_Total -> 7051.82 | D36: Hauptnutzfläche m²
B37: Aktueller Ø Mietzins CHF/m²/Jahr | C37: =C34/C36 -> 291.41039 | D37: Aktueller Mietertrag / HNF
B38: Nötiger Ø Mietzins CHF/m²/Jahr | C38: =C33/C36 -> 338.74234 | D38: Bei gleicher HNF
B39: Erforderliche Mietzins-Erhöhung (%) | C39: =C33/C34-1 -> 0.16242369 | D39: Im Mittel über alle Nutzungen
B42: 5. Empfehlungen zur Schliessung der Rendite-Lücke
B43: Option A: Mietzinse marktnäher ansetzen | C43: EG Gewerbe von 140-150 → 200-250 CHF/m²; OG Büro von 170 → 220 CHF/m²; AT (Wotel) bereits hoch (370-400) | G43: Bringt grössten Effekt (+25-30% Mietertrag möglich)
B44: Option B: Nebenflächen-Umlage (Methabau) | C44: Explizite Umlage Treppenhaus/WC bringt zusätzlich CHF ~25-50k/Jahr/Haus | G44: Best Practice in CH, einfach umsetzbar
B45: Option C: Wotel-Konzept ausweiten | C45: Anteil Wotel (höchste m²-Rendite) im Gebäudemix erhöhen falls Markt es zulässt | G45: Erfordert Architekturanpassung
B46: Option D: Parkplatz-Erträge integrieren | C46: Methabau Leubern: CHF 304'500/Jahr für 199 PP – im Campus Elgg noch nicht modelliert | G46: Direkt addierbar zum Mietertrag
B47: Option E: PV-Anlage als Ertrag | C47: Leubern: CHF 65'465/Jahr Prognose aus PV+ZEV – noch nicht im Modell | G47: Zusatzertrag und ESG-Argument
B49: FAZIT (aktualisiert nach +20% Mietzinserhöhung & Landwert-Umlagerung): STATUS: • Anlagekosten: CHF 37.5 Mio. / 75 Mio. – exakt KV März 2026 ✓ • Mietzinse: alle Annahmen-Zellen in 03 Flächenspiegel um +20% erhöht (z.B. EG Gewerbe 168-180, OG Büro 204-210, AT Wotel 444-480 CHF/m²) • Modellierter Soll-Mietertrag E1: ca. CHF 2'055'000 (alt CHF 1'712'000) • Plus Nebenerträge (Parkplätze + PV): CHF 160'000/Jahr • = Gesamt-Mietertrag E1: ca. CHF 2'215'000/Jahr → Bruttorendite ~5.91% ZIELGEGENÜBERSTELLUNG: • Ziel laut KV: 6.37% – wir sind bei ~5.91% → Lücke nur noch –46 bp • Mit weiteren +5-8% auf den Mietzinsen wären wir im Zielsegment • Alternative: PV-Ertrag konservativ angesetzt (20k pro Haus) – Methabau-Leubern realisiert 65k pro Gebäude LANDWERT-PERSPEKTIVE (siehe 05 Kostenschätzung): • Sicht 1 (KV-Buchung): BKP 0 = 7.5 Mio. → impliziter Landwert CHF 660/m² (E1) • Sicht 2 (wirtschaftlich): 80% von BKP 1 sind Quartierplan/Erschliessung → wandern zu BKP 0 → BKP 0 effektiv: 10.5 Mio. → Landwert CHF 924/m² (E1) • Das ist marktnäher (Marktreferenz Region Winterthur Gewerbezone CHF 650-800/m²) und zeigt: Der Bauherr/Investor hat bereits 3.0 Mio. CHF Entwicklungswertschöpfung auf dem Grundstück realisiert • Wichtig: Diese Umlagerung verändert die Bruttorendite NICHT (Anlagekosten bleiben gleich), aber sie zeigt die wahre wirtschaftliche Werthaltigkeit des Investments und stärkt die Investorenargumentation.

Sheet 11 Parkplätze & Nebenerträge
B2: Parkplätze & Nebenerträge – Schätzung aus Umgebungsplan
B3: Parkplatz-Anzahl geschätzt aus Umgebungsplan Campus Elgg (Etappe 1 + 2). Preise aus Methabau-Leubern-Referenz (Stand 09.09.2025): Aussen-PP CHF 100/Monat, Tiefgarage Dauer CHF 150/Monat, Motorrad CHF 5/Monat.
B5: 1. Annahmen Parkplatz-Preise (gem. Methabau-Leubern-Referenz)
B6: Parkplatz-Typ | C6: Einheit | D6: CHF/Monat | F6: CHF/Jahr (berechnet)
B7: Aussenparkplatz (teilw. bewirtschaftet) | C7: Stk | D7: 100 | E7: =D7*12 -> 1200 | F7: Methabau Leubern: Besucher-/Aussen-PP
B8: Tiefgaragenplatz (Dauermiete) | C8: Stk | D8: 150 | E8: =D8*12 -> 1800 | F8: Methabau Leubern: TG Dauermietplatz
B9: Motorradabstellplatz | C9: Stk | D9: 5 | E9: =D9*12 -> 60 | F9: Methabau Leubern: Motorrad
B12: 2. Anzahl Parkplätze (Schätzung aus Umgebungsplan)
B13: Parkplatz-Typ | D13: Etappe 1 | E13: Etappe 2 | F13: Total | G13: Annahme/Standort
B14: Aussenparkplätze | D14: 38 | E14: 52 | F14: =D14+E14 -> 90 | G14: Norden A/D, zwischen Häusern, Süd, Obermühle-Seite
B15: Tiefgaragenplätze (Dauer) | D15: 30 | E15: 30 | F15: =D15+E15 -> 60 | G15: UG je Etappe, ca. 30 Stellplätze
B16: Motorradabstellplätze | D16: 8 | E16: 8 | F16: =D16+E16 -> 16 | G16: Aussenbereich (gem. PBG §90 TG)
B17: TOTAL Parkplätze | D17: =SUM(D14:D16) -> 76 | E17: =SUM(E14:E16) -> 90 | F17: =D17+E17 -> 166
B19: 3. Mietertrag Parkplätze pro Jahr
B20: Position | D20: Etappe 1 | E20: Etappe 2 | F20: Total | G20: Berechnung
B21: Aussenparkplätze | D21: =D14*E7 -> 45600 | E21: =E14*E7 -> 62400 | F21: =D21+E21 -> 108000 | G21: Anzahl × CHF/Jahr
B22: Tiefgaragenplätze | D22: =D15*E8 -> 54000 | E22: =E15*E8 -> 54000 | F22: =D22+E22 -> 108000 | G22: Anzahl × CHF/Jahr
B23: Motorradabstellplätze | D23: =D16*E9 -> 480 | E23: =E16*E9 -> 480 | F23: =D23+E23 -> 960 | G23: Anzahl × CHF/Jahr
B24: TOTAL Parkplatz-Ertrag p.a. | D24: =SUM(D21:D23) -> 100080 | E24: =SUM(E21:E23) -> 116880 | F24: =D24+E24 -> 216960
B26: 4. Photovoltaik-Ertrag (Annahme analog Methabau)
B27: Annahme PV-Ertrag pro Haus / Jahr | D27: 20000 | E27: Konservativ; Methabau Leubern: CHF 65'465 für 1 grosses Gebäude inkl. ZEV
B28: PV-Ertrag Total p.a. | D28: =D27*Hauser_E1 -> 60000 | E28: =D27*Hauser_E2 -> 60000 | F28: =D28+E28 -> 120000
B30: 5. TOTAL Nebenerträge (Parkplätze + PV)
B31: GESAMT-NEBENERTRAG p.a. | D31: =PP_Ertrag_E1+PV_Ertrag_E1 -> 160080 | E31: =PP_Ertrag_E2+PV_Ertrag_E2 -> 176880 | F31: =D31+E31 -> 336960
B33: 6. Auswirkung auf Bruttorendite
B34: Soll-Mietertrag HNF (Modell) | D34: =Mietertrag_E1_Soll -> 2054973.6 | E34: =Mietertrag_Total_Soll-Mietertrag_E1_Soll -> 2096073.1 | F34: =Mietertrag_Total_Soll -> 4151046.7
B35: + Nebenerträge (PP + PV) | D35: =Nebenertrag_E1 -> 160080 | E35: =Nebenertrag_E2 -> 176880 | F35: =Nebenertrag_Total -> 336960
B36: Σ Gesamtmietertrag inkl. Nebenerträge | D36: =D34+D35 -> 2215053.6 | E36: =E34+E35 -> 2272953.1 | F36: =F34+F35 -> 4488006.7
B37: Anlagekosten BKP 0-9 | D37: =Invest_E1 -> 37500000 | E37: =Invest_E2 -> 37500000 | F37: =Invest_Total -> 75000000
B38: Bruttorendite vorher (nur HNF) | D38: =Mietertrag_E1_Soll/Invest_E1 -> 0.054799296 | F38: =Mietertrag_Total_Soll/Invest_Total -> 0.055347289
B39: Bruttorendite mit Nebenerträgen | D39: =D36/D37 -> 0.059068096 | F39: =F36/F37 -> 0.059840089
B40: Verbesserung in Basispunkten | D40: =(D39-D38)*10000 -> 42.688 | F40: =(F39-F38)*10000 -> 44.928

Sheet 12 Glossar
B2: Glossar – Fachbegriffe Immobilienentwicklung & Renditemodell
B3: Definitionen der im Modell verwendeten Begriffe – Schweizer Immobilienpraxis und SIA-Standards.
B5: Flächen & Volumen
B6: GF | C6: Geschossfläche | D6: Summe aller oberirdischen und unterirdischen Bodenflächen eines Gebäudes inkl. Konstruktionsflächen, gem. SIA 416.
B7: GV | C7: Geschossvolumen | D7: Bruttovolumen des Gebäudes nach SIA 416 – massgebliche Grösse für Kostenschätzung CHF/m³.
B8: HNF | C8: Hauptnutzfläche | D8: Vermietbare Fläche für die Hauptnutzung (Büro, Gewerbe, Wohnen). Ohne Treppenhaus, WC, Technik.
B9: NGF | C9: Nettogeschossfläche | D9: Bodenfläche ohne tragende und nichttragende Konstruktionsflächen. In Methabau-Berechnungen die Bezugsgrösse.
B10: NF | C10: Nutzfläche | D10: Oberbegriff: HNF (Hauptnutzfläche) + NNF (Nebennutzfläche).
B11: NNF | C11: Nebennutzfläche | D11: Nebenflächen wie Lager, Technikraum, Archiv – mit geringerer Wertigkeit als HNF.
B12: VF | C12: Verkehrsfläche | D12: Treppenhäuser, Korridore, Erschliessung. Im Methabau-Modell mit eigenem Mietpreis.
B13: FF | C13: Funktionsfläche | D13: Technikräume, Lüftung, Sprinkler – meist nicht vermietet.
B14: KF | C14: Konstruktionsfläche | D14: Tragende Wände, Stützen, Fassade – nicht vermietbar.
B15: BGF | C15: Bruttogeschossfläche | D15: Gesamtfläche inkl. Konstruktion (entspricht in CH oft GF).
B16: AZ | C16: Ausnützungsziffer | D16: Verhältnis anrechenbare GF / Grundstücksfläche. In BZO definiert (z.B. 0.8 für Gewerbezone).
B17: aGSF | C17: Anrechenbare Grundstücksfläche | D17: Teil des Grundstücks in der jeweiligen Bauzone, der für AZ-Berechnung zählt.
B18: Baukostenplan (BKP)
B19: BKP 0 | C19: Grundstück | D19: Landerwerb, Nebenkosten Grundbuch, Erschliessungsabgaben, Quartierplankosten.
B20: BKP 1 | C20: Vorbereitungsarbeiten | D20: Abbruch, Aushub, Spezialtiefbau, Werkleitungen. Ein Teil ist oft 'verkappter' Landwert.
B21: BKP 2 | C21: Gebäude | D21: Hauptkostenblock: Rohbau, Ausbau, Haustechnik. Massgebliche CHF/m³ GV-Kennzahl.
B22: BKP 3 | C22: Betriebseinrichtungen | D22: Spezialeinrichtungen für Mieter (Hotel, Gastro, Industrie).
B23: BKP 4 | C23: Umgebung | D23: Aussenräume, Plätze, Wege, Begrünung, Aussenparkplätze.
B24: BKP 5 | C24: Baunebenkosten | D24: Bewilligungen, Versicherungen, Anschlussgebühren, Abgaben.
B25: BKP 6 | C25: Honorare | D25: Generalplaner, Architekt, Ingenieure, Spezialplaner.
B26: BKP 7 | C26: Reserve / TU | D26: Reserve für Unvorhergesehenes, Totalunternehmer-Marge, Baumanagement.
B27: BKP 8 | C27: Verkauf & Vermarktung | D27: Marketing, Erstvermietung, Vermarktungsleistungen.
B28: BKP 9 | C28: Bauherrenkosten | D28: Bauherrenleistungen, Projektsteuerung, Investorenkosten.
B29: Rendite-Kennzahlen
B30: Bruttorendite | C30: (Brutto-Mietertrag) | D30: Soll-Mietertrag p.a. / Anlagekosten. Marktstandard in CH, ohne Bewirtschaftungskosten.
B31: Nettorendite | C31: (Netto-Mietertrag) | D31: Nettomietertrag (nach Bewirtschaftung) / Anlagekosten. Realistischer für Investorenbeurteilung.
B32: EK-Rendite | C32: (Eigenkapital-Rendite) | D32: Cash-on-Cash = (NOI - FK-Zinsen) / Eigenkapital. Zeigt Leverage-Effekt.
B33: NOI | C33: Net Operating Income | D33: Nettomietertrag nach Bewirtschaftungs- und Unterhaltskosten, vor Finanzierung.
B34: DCF | C34: Discounted Cash Flow | D34: Barwertmethode: zukünftige Cashflows abdiskontiert. Marktstandard für institutionelle Investoren.
B35: Kapitalisierungssatz | C35: (Cap Rate) | D35: Rendite-Anforderung des Marktes. Niedrig = teurer Markt. CH Gewerbe aktuell ca. 4.0–5.5%.
B36: DSCR | C36: Debt Service Coverage Ratio | D36: NOI / Schuldendienst. Bank-Kennzahl: >1.20 erwartet.
B37: LTV | C37: Loan-to-Value | D37: Fremdkapital / Verkehrswert. Bank-Limit Gewerbe meist 65–70%.
B38: Vertrag & Vermietung
B39: Soll-Mietzins | C39: (brutto) | D39: Vereinbarter Mietzins ohne Berücksichtigung von Mietausfall.
B40: Effektiv-Mietzins | C40: (netto) | D40: Soll-Mietzins abzüglich Leerstand und Mietausfall.
B41: Leerstand | C41: (Vacancy) | D41: Anteil unvermieteter Fläche. CH Gewerbe markttypisch 3–8%, Wohnen 1–3%.
B42: Mietausfall | D42: Tatsächliche Mietminderung durch Leerstand und Zahlungsausfälle.
...
